Workbook

Sheet Overview
A1: 12-Week Upper / Lower / Full Body Tracker
A3: Schedule | D3: Phase Map
A4: Mon | B4: Upper | D4: Weeks 1-4 | E4: Accumulation | F4: RIR 2-3 — build base, dial form
A5: Tue | B5: Rest | D5: Weeks 5-8 | E5: Intensification | F5: RIR 1-2 — push working weight
A6: Wed | B6: Lower | D6: Weeks 9-11 | E6: Peak | F6: RIR 0-1 — max stimulus
A7: Thu | B7: Rest | D7: Week 12 | E7: Deload | F7: 50% weight, 2 sets x 8
A8: Fri | B8: Full Body
A9: Sat | B9: Rest / Walk
A10: Sun | B10: Rest / Walk
A12: Progression Rules
A13: • Double progression: hit top of rep range on ALL 3 sets → next session, +2.5-5kg compounds, +1-2kg isolations, drop reps to bottom of range
A14: • Warm-up: 5 min cardio + dynamic mobility, then 2 ramp sets (50%, 75%) on first compound only
A15: • Rest: 2-3 min compounds, 60-90s isolations
A16: • Stop a set if form breaks — not when you hit the rep target
A17: • If joint pain (not muscle soreness) > 3 days, swap the exercise
A18: • Sleep 7+ hrs, protein 1.6-2 g/kg bodyweight
A19: • Stalled 2 weeks on same exercise? Swap variation (e.g., flat → incline).
A22: How to Use
A23: 1. Each week tab = one training week with 3 workouts (Upper, Lower, Full).
A24: 2. Log Weight × Reps for each set. Notes column for form cues, RPE, soreness.
A25: 3. "Top Set Volume" auto-calculates (weight × reps of set 3).
... A27: 5. Color guide: Green = Accumulation · Yellow = Intensification · Orange = Peak · Grey = Deload.

Sheet Wk01
A1: Week 1 — Accumulation (RIR 2-3)
A3: Upper
A4: Exercise | B4: Target Reps | C4: S1 Wt | D4: S1 Reps | E4: S2 Wt | F4: S2 Reps | G4: S3 Wt | H4: S3 Reps | I4: Top Set Vol | J4: Hit Top? | K4: Notes
A5: DB Bench Press (neutral/30° incline) | B5: 8-12 | C5: 35 | D5: 10 | E5: 35 | F5: 10 | G5: 35 | H5: 10 | I5: =IF(AND(G5<>"",H5<>""),G5*H5,"") -> 350 | J5: =IF(H5="","",IF(H5>=VALUE(LEFT(MID(B5,FIND("-",B5)+1,2),2)),"✓",""))
A6: Chest-Supported DB Row | B6: 8-12 | C6: 25 | D6: 12 | E6: 30 | F6: 12 | G6: 35 | H6: 12 | I6: =IF(AND(G6<>"",H6<>""),G6*H6,"") -> 420 | J6: =IF(H6="","",IF(H6>=VALUE(LEFT(MID(B6,FIND("-",B6)+1,2),2)),"✓","")) -> ✓
A7: Seated DB Shoulder Press | B7: 8-12 | C7: 20 | D7: 12 | E7: 25 | F7: 12 | G7: 25 | H7: 10 | I7: =IF(AND(G7<>"",H7<>""),G7*H7,"") -> 250 | J7: =IF(H7="","",IF(H7>=VALUE(LEFT(MID(B7,FIND("-",B7)+1,2),2)),"✓",""))
A8: DB Lateral Raise | B8: 12-15 | C8: 10 | D8: 15 | E8: 15 | F8: 15 | G8: 15 | H8: 15 | I8: =IF(AND(G8<>"",H8<>""),G8*H8,"") -> 225 | J8: =IF(H8="","",IF(H8>=VALUE(LEFT(MID(B8,FIND("-",B8)+1,2),2)),"✓","")) -> ✓
A9: DB Hammer Curl + OH Triceps Ext (SS) | B9: 12-15 | C9: 20 | D9: 15 | E9: 20 | F9: 15 | G9: 25 | H9: 12 | I9: =IF(AND(G9<>"",H9<>""),G9*H9,"") -> 300 | J9: =IF(H9="","",IF(H9>=VALUE(LEFT(MID(B9,FIND("-",B9)+1,2),2)),"✓",""))
B10: 12-15 | C10: 40 | D10: 15 | E10: 40 | F10: 15 | G10: 40 | H10: 15 | I10: =IF(AND(G10<>"",H10<>""),G10*H10,"") -> 600 | J10: =IF(H10="","",IF(H10>=VALUE(LEFT(MID(B10,FIND("-",B10)+1,2),2)),"✓","")) -> ✓
A11: Lower
A12: Exercise | B12: Target Reps | C12: S1 Wt | D12: S1 Reps | E12: S2 Wt | F12: S2 Reps | G12: S3 Wt | H12: S3 Reps | I12: Top Set Vol | J12: Hit Top? | K12: Notes
A13: Box squat | B13: 8-12 | C13: 85 | D13: 12 | E13: 105 | F13: 12 | G13: 115 | H13: 12 | I13: =IF(AND(G13<>"",H13<>""),G13*H13,"") -> 1380 | J13: =IF(H13="","",IF(H13>=VALUE(LEFT(MID(B13,FIND("-",B13)+1,2),2)),"✓","")) -> ✓
A14: Lying / Seated Leg Curl | B14: 8-12 | C14: 80 | D14: 12 | E14: 90 | F14: 8 | G14: 90 | H14: 8 | I14: =IF(AND(G14<>"",H14<>""),G14*H14,"") -> 720 | J14: =IF(H14="","",IF(H14>=VALUE(LEFT(MID(B14,FIND("-",B14)+1,2),2)),"✓",""))
A15: Smith Bulgarian Split Squat | B15: 8-12 / leg | C15: 20 | D15: 8 | E15: 20 | F15: 10 | G15: 20 | H15: 12 | I15: =IF(AND(G15<>"",H15<>""),G15*H15,"") -> 240 | J15: =IF(H15="","",IF(H15>=VALUE(LEFT(MID(B15,FIND("-",B15)+1,2),2)),"✓","")) -> ✓
A16: DB Hip Thrust | B16: 12-15 | C16: 12 | D16: 135 | E16: 12 | F16: 135 | G16: 10 | H16: 135 | I16: =IF(AND(G16<>"",H16<>""),G16*H16,"") -> 1350 | J16: =IF(H16="","",IF(H16>=VALUE(LEFT(MID(B16,FIND("-",B16)+1,2),2)),"✓","")) -> ✓
A17: Leg Extension + Standing Calf Raise (SS) | B17: 12-15 / 12-15 | C17: 90 | D17: 15 | E17: 90 | F17: 15 | G17: 90 | H17: 15 | I17: =IF(AND(G17<>"",H17<>""),G17*H17,"") -> 1350 | J17: =IF(H17="","",IF(H17>=VALUE(LEFT(MID(B17,FIND("-",B17)+1,2),2)),"✓","")) -> ✓
B18: 12-15 / 12-15 | C18: 50 | D18: 15 | E18: 70 | F18: 15 | G18: 70 | H18: 15 | I18: =IF(AND(G18<>"",H18<>""),G18*H18,"") -> 1050 | J18: =IF(H18="","",IF(H18>=VALUE(LEFT(MID(B18,FIND("-",B18)+1,2),2)),"✓","")) -> ✓
A19: Full Body
A20: Exercise | B20: Target Reps | C20: S1 Wt | D20: S1 Reps | E20: S2 Wt | F20: S2 Reps | G20: S3 Wt | H20: S3 Reps | I20: Top Set Vol | J20: Hit Top? | K20: Notes
A21: Barbell deadlift | B21: 8-12 | C21: 115 | D21: 12 | E21: 115 | F21: 12 | G21: 115 | H21: 12 | I21: =IF(AND(G21<>"",H21<>""),G21*H21,"") -> 1380 | J21: =IF(H21="","",IF(H21>=VALUE(LEFT(MID(B21,FIND("-",B21)+1,2),2)),"✓","")) -> ✓
A22: DB Floor Press / Push-Up | B22: 8-12 | C22: 135 | D22: 15 | E22: 135 | F22: 12 | G22: 135 | H22: 15 | I22: =IF(AND(G22<>"",H22<>""),G22*H22,"") -> 2025 | J22: =IF(H22="","",IF(H22>=VALUE(LEFT(MID(B22,FIND("-",B22)+1,2),2)),"✓","")) -> ✓
A23: One-Arm DB Row | B23: 8-12 / side | C23: 40 | D23: 12 | E23: 50 | F23: 12 | G23: 50 | H23: 12 | I23: =IF(AND(G23<>"",H23<>""),G23*H23,"") -> 600 | J23: =IF(H23="","",IF(H23>=VALUE(LEFT(MID(B23,FIND("-",B23)+1,2),2)),"✓","")) -> ✓
A24: DB Reverse Lunge | B24: 12-15 / leg | C24: 0 | D24: 15 | E24: 20 | F24: 15 | G24: 20 | H24: 15 | I24: =IF(AND(G24<>"",H24<>""),G24*H24,"") -> 300 | J24: =IF(H24="","",IF(H24>=VALUE(LEFT(MID(B24,FIND("-",B24)+1,2),2)),"✓","")) -> ✓
A25: Pull-Up / Lat Pulldown | B25: 8-12 | C25: 100 | D25: 10 | E25: 100 | F25: 10 | G25: 100 | H25: 10 | I25: =IF(AND(G25<>"",H25<>""),G25*H25,"") -> 1000 | J25: =IF(H25="","",IF(H25>=VALUE(LEFT(MID(B25,FIND("-",B25)+1,2),2)),"✓",""))
A28: Blue cells = your inputs. Top Set Vol & Hit Top? auto-calculate.

Sheet Wk02
A1: Week 2 — Accumulation (RIR 2-3)
A3: Upper
A4: Exercise | B4: Target Reps | C4: S1 Wt | D4: S1 Reps | E4: S2 Wt | F4: S2 Reps | G4: S3 Wt | H4: S3 Reps | I4: Top Set Vol | J4: Hit Top? | K4: Notes
A5: DB Bench Press (neutral/30° incline) | B5: 8-12 | C5: 35 | D5: 12 | E5: 40 | F5: 8 | G5: 40 | H5: 8 | I5: =IF(AND(G5<>"",H5<>""),G5*H5,"") -> 320 | J5: =IF(H5="","",IF(H5>=VALUE(LEFT(MID(B5,FIND("-",B5)+1,2),2)),"✓",""))
A6: Chest-Supported DB Row | B6: 8-12 | C6: 35 | D6: 12 | E6: 40 | F6: 10 | G6: 40 | H6: 11 | I6: =IF(AND(G6<>"",H6<>""),G6*H6,"") -> 440 | J6: =IF(H6="","",IF(H6>=VALUE(LEFT(MID(B6,FIND("-",B6)+1,2),2)),"✓",""))
A7: Seated DB Shoulder Press | B7: 8-12 | C7: 20 | D7: 15 | E7: 20 | F7: 15 | G7: 20 | H7: 15 | I7: =IF(AND(G7<>"",H7<>""),G7*H7,"") -> 300 | J7: =IF(H7="","",IF(H7>=VALUE(LEFT(MID(B7,FIND("-",B7)+1,2),2)),"✓","")) -> ✓
A8: DB Lateral Raise | B8: 12-15 | C8: 15 | D8: 15 | E8: 15 | F8: 15 | G8: 15 | H8: 15 | I8: =IF(AND(G8<>"",H8<>""),G8*H8,"") -> 225 | J8: =IF(H8="","",IF(H8>=VALUE(LEFT(MID(B8,FIND("-",B8)+1,2),2)),"✓","")) -> ✓
A9: DB Hammer Curl + OH Triceps Ext (SS) | B9: 12-15 | C9: 20 | D9: 15 | E9: 20 | F9: 14 | G9: 20 | H9: 12 | I9: =IF(AND(G9<>"",H9<>""),G9*H9,"") -> 240 | J9: =IF(H9="","",IF(H9>=VALUE(LEFT(MID(B9,FIND("-",B9)+1,2),2)),"✓",""))
B10: 12-15 | C10: 40 | D10: 14 | E10: 40 | F10: 13 | G10: 40 | H10: 12 | I10: =IF(AND(G10<>"",H10<>""),G10*H10,"") -> 480 | J10: =IF(H10="","",IF(H10>=VALUE(LEFT(MID(B10,FIND("-",B10)+1,2),2)),"✓",""))
A11: Lower
A12: Exercise | B12: Target Reps | C12: S1 Wt | D12: S1 Reps | E12: S2 Wt | F12: S2 Reps | G12: S3 Wt | H12: S3 Reps | I12: Top Set Vol | J12: Hit Top? | K12: Notes
A13: Box squat | B13: 8-12 | C13: 115 | D13: 12 | E13: 115 | F13: 12 | G13: 115 | H13: 12 | I13: =IF(AND(G13<>"",H13<>""),G13*H13,"") -> 1380 | J13: =IF(H13="","",IF(H13>=VALUE(LEFT(MID(B13,FIND("-",B13)+1,2),2)),"✓","")) -> ✓
A14: Lying / Seated Leg Curl | B14: 8-12 | C14: 80 | D14: 12 | E14: 90 | F14: 10 | G14: 90 | H14: 10 | I14: =IF(AND(G14<>"",H14<>""),G14*H14,"") -> 900 | J14: =IF(H14="","",IF(H14>=VALUE(LEFT(MID(B14,FIND("-",B14)+1,2),2)),"✓",""))
A15: Smith Bulgarian Split Squat | B15: 8-12 / leg | C15: 20 | D15: 12 | E15: 20 | F15: 12 | G15: 20 | H15: 12 | I15: =IF(AND(G15<>"",H15<>""),G15*H15,"") -> 240 | J15: =IF(H15="","",IF(H15>=VALUE(LEFT(MID(B15,FIND("-",B15)+1,2),2)),"✓","")) -> ✓
A16: DB Hip Thrust | B16: 12-15 | C16: 135 | D16: 14 | E16: 135 | F16: 14 | G16: 135 | H16: 14 | I16: =IF(AND(G16<>"",H16<>""),G16*H16,"") -> 1890 | J16: =IF(H16="","",IF(H16>=VALUE(LEFT(MID(B16,FIND("-",B16)+1,2),2)),"✓",""))
A17: Leg Extension + Standing Calf Raise (SS) | B17: 12-15 / 12-15 | C17: 90 | D17: 15 | E17: 90 | F17: 13 | G17: 90 | H17: 13 | I17: =IF(AND(G17<>"",H17<>""),G17*H17,"") -> 1170 | J17: =IF(H17="","",IF(H17>=VALUE(LEFT(MID(B17,FIND("-",B17)+1,2),2)),"✓",""))
B18: 12-15 / 12-15 | C18: 50 | D18: 15 | E18: 55 | F18: 15 | G18: 55 | H18: 14 | I18: =IF(AND(G18<>"",H18<>""),G18*H18,"") -> 770 | J18: =IF(H18="","",IF(H18>=VALUE(LEFT(MID(B18,FIND("-",B18)+1,2),2)),"✓",""))
A19: Full Body
A20: Exercise | B20: Target Reps | C20: S1 Wt | D20: S1 Reps | E20: S2 Wt | F20: S2 Reps | G20: S3 Wt | H20: S3 Reps | I20: Top Set Vol | J20: Hit Top? | K20: Notes
A21: Barbell deadlift | B21: 8-12 | C21: 115 | D21: 12 | E21: 120 | F21: 12 | G21: 112 | H21: 11 | I21: =IF(AND(G21<>"",H21<>""),G21*H21,"") -> 1232 | J21: =IF(H21="","",IF(H21>=VALUE(LEFT(MID(B21,FIND("-",B21)+1,2),2)),"✓",""))
A22: DB Floor Press / Push-Up | B22: 8-12 | C22: 135 | D22: 19 | E22: 135 | F22: 14 | G22: 135 | H22: 12 | I22: =IF(AND(G22<>"",H22<>""),G22*H22,"") -> 1620 | J22: =IF(H22="","",IF(H22>=VALUE(LEFT(MID(B22,FIND("-",B22)+1,2),2)),"✓","")) -> ✓
A23: One-Arm DB Row | B23: 8-12 / side | C23: 50 | D23: 12 | E23: 60 | F23: 8 | G23: 60 | H23: 9 | I23: =IF(AND(G23<>"",H23<>""),G23*H23,"") -> 540 | J23: =IF(H23="","",IF(H23>=VALUE(LEFT(MID(B23,FIND("-",B23)+1,2),2)),"✓",""))
A24: DB Reverse Lunge | B24: 12-15 / leg | C24: 20 | D24: 15 | E24: 30 | F24: 15 | G24: 30 | H24: 10 | I24: =IF(AND(G24<>"",H24<>""),G24*H24,"") -> 300 | J24: =IF(H24="","",IF(H24>=VALUE(LEFT(MID(B24,FIND("-",B24)+1,2),2)),"✓",""))
A25: Pull-Up / Lat Pulldown | B25: 8-12 | C25: 100 | D25: 11 | E25: 100 | F25: 10 | G25: 100 | H25: 8 | I25: =IF(AND(G25<>"",H25<>""),G25*H25,"") -> 800 | J25: =IF(H25="","",IF(H25>=VALUE(LEFT(MID(B25,FIND("-",B25)+1,2),2)),"✓",""))
A28: Blue cells = your inputs. Top Set Vol & Hit Top? auto-calculate.

Sheet Wk03
A1: Week 3 — Accumulation (RIR 2-3)
A3: Upper
A4: Exercise | B4: Target Reps | C4: S1 Wt | D4: S1 Reps | E4: S2 Wt | F4: S2 Reps | G4: S3 Wt | H4: S3 Reps | I4: Top Set Vol | J4: Hit Top? | K4: Notes
A5: DB Bench Press (neutral/30° incline) | B5: 8-12 | C5: 40 | D5: 12 | E5: 40 | F5: 8 | G5: 40 | H5: 9 | I5: =IF(AND(G5<>"",H5<>""),G5*H5,"") -> 360 | J5: =IF(H5="","",IF(H5>=VALUE(LEFT(MID(B5,FIND("-",B5)+1,2),2)),"✓",""))
A6: Chest-Supported DB Row | B6: 8-12 | C6: 40 | D6: 12 | E6: 40 | F6: 12 | G6: 40 | H6: 12 | I6: =IF(AND(G6<>"",H6<>""),G6*H6,"") -> 480 | J6: =IF(H6="","",IF(H6>=VALUE(LEFT(MID(B6,FIND("-",B6)+1,2),2)),"✓","")) -> ✓
A7: Seated DB Shoulder Press | B7: 8-12 | C7: 20 | D7: 15 | E7: 20 | F7: 13 | G7: 20 | H7: 14 | I7: =IF(AND(G7<>"",H7<>""),G7*H7,"") -> 280 | J7: =IF(H7="","",IF(H7>=VALUE(LEFT(MID(B7,FIND("-",B7)+1,2),2)),"✓","")) -> ✓
A8: DB Lateral Raise | B8: 12-15 | C8: 15 | D8: 15 | E8: 15 | F8: 11 | G8: 15 | H8: 12 | I8: =IF(AND(G8<>"",H8<>""),G8*H8,"") -> 180 | J8: =IF(H8="","",IF(H8>=VALUE(LEFT(MID(B8,FIND("-",B8)+1,2),2)),"✓",""))
A9: DB Hammer Curl + OH Triceps Ext (SS) | B9: 12-15 | C9: 20 | D9: 15 | E9: 20 | F9: 15 | G9: 20 | H9: 15 | I9: =IF(AND(G9<>"",H9<>""),G9*H9,"") -> 300 | J9: =IF(H9="","",IF(H9>=VALUE(LEFT(MID(B9,FIND("-",B9)+1,2),2)),"✓","")) -> ✓
B10: 12-15 | C10: 40 | D10: 15 | E10: 40 | F10: 13 | G10: 40 | H10: 13 | I10: =IF(AND(G10<>"",H10<>""),G10*H10,"") -> 520 | J10: =IF(H10="","",IF(H10>=VALUE(LEFT(MID(B10,FIND("-",B10)+1,2),2)),"✓",""))
A11: Lower
A12: Exercise | B12: Target Reps | C12: S1 Wt | D12: S1 Reps | E12: S2 Wt | F12: S2 Reps | G12: S3 Wt | H12: S3 Reps | I12: Top Set Vol | J12: Hit Top? | K12: Notes
A13: Box squat | B13: 8-12 | C13: 115 | D13: 12 | E13: 115 | F13: 12 | G13: 120 | H13: 10 | I13: =IF(AND(G13<>"",H13<>""),G13*H13,"") -> 1200 | J13: =IF(H13="","",IF(H13>=VALUE(LEFT(MID(B13,FIND("-",B13)+1,2),2)),"✓",""))
A14: Lying / Seated Leg Curl | B14: 8-12 | C14: 90 | D14: 12 | E14: 100 | F14: 11 | G14: 100 | H14: 11 | I14: =IF(AND(G14<>"",H14<>""),G14*H14,"") -> 1100 | J14: =IF(H14="","",IF(H14>=VALUE(LEFT(MID(B14,FIND("-",B14)+1,2),2)),"✓",""))
A15: Smith Bulgarian Split Squat | B15: 8-12 / leg | C15: 20 | D15: 12 | E15: 20 | F15: 12 | G15: 20 | H15: 12 | I15: =IF(AND(G15<>"",H15<>""),G15*H15,"") -> 240 | J15: =IF(H15="","",IF(H15>=VALUE(LEFT(MID(B15,FIND("-",B15)+1,2),2)),"✓","")) -> ✓
A16: DB Hip Thrust | B16: 12-15 | C16: 135 | D16: 12 | E16: 135 | F16: 12 | G16: 135 | I16: =IF(AND(G16<>"",H16<>""),G16*H16,"") | J16: =IF(H16="","",IF(H16>=VALUE(LEFT(MID(B16,FIND("-",B16)+1,2),2)),"✓",""))
A17: Leg Extension + Standing Calf Raise (SS) | B17: 12-15 / 12-15 | C17: 90 | D17: 12 | E17: 90 | F17: 12 | G17: 90 | H17: 10 | I17: =IF(AND(G17<>"",H17<>""),G17*H17,"") -> 900 | J17: =IF(H17="","",IF(H17>=VALUE(LEFT(MID(B17,FIND("-",B17)+1,2),2)),"✓",""))
B18: 12-15 / 12-15 | C18: 55 | D18: 15 | E18: 55 | F18: 15 | G18: 55 | H18: 15 | I18: =IF(AND(G18<>"",H18<>""),G18*H18,"") -> 825 | J18: =IF(H18="","",IF(H18>=VALUE(LEFT(MID(B18,FIND("-",B18)+1,2),2)),"✓","")) -> ✓
A19: Full Body
A20: Exercise | B20: Target Reps | C20: S1 Wt | D20: S1 Reps | E20: S2 Wt | F20: S2 Reps | G20: S3 Wt | H20: S3 Reps | I20: Top Set Vol | J20: Hit Top? | K20: Notes
A21: Barbell deadlift | B21: 8-12 | C21: 115 | D21: 12 | E21: 120 | F21: 12 | G21: 125 | H21: 12 | I21: =IF(AND(G21<>"",H21<>""),G21*H21,"") -> 1500 | J21: =IF(H21="","",IF(H21>=VALUE(LEFT(MID(B21,FIND("-",B21)+1,2),2)),"✓","")) -> ✓
A22: DB Floor Press / Push-Up | B22: 8-12 | C22: 135 | D22: 18 | E22: 135 | F22: 13 | G22: 135 | H22: 10 | I22: =IF(AND(G22<>"",H22<>""),G22*H22,"") -> 1350 | J22: =IF(H22="","",IF(H22>=VALUE(LEFT(MID(B22,FIND("-",B22)+1,2),2)),"✓",""))
A23: One-Arm DB Row | B23: 8-12 / side | C23: 60 | D23: 10 | E23: 60 | F23: 10 | G23: 60 | H23: 10 | I23: =IF(AND(G23<>"",H23<>""),G23*H23,"") -> 600 | J23: =IF(H23="","",IF(H23>=VALUE(LEFT(MID(B23,FIND("-",B23)+1,2),2)),"✓",""))
A24: DB Reverse Lunge | B24: 12-15 / leg | C24: 30 | D24: 15 | E24: 30 | F24: 15 | G24: 60 | H24: 15 | I24: =IF(AND(G24<>"",H24<>""),G24*H24,"") -> 900 | J24: =IF(H24="","",IF(H24>=VALUE(LEFT(MID(B24,FIND("-",B24)+1,2),2)),"✓","")) -> ✓
A25: Pull-Up / Lat Pulldown | B25: 8-12 | C25: 100 | D25: 12 | E25: 100 | F25: 8 | G25: 100 | H25: 8 | I25: =IF(AND(G25<>"",H25<>""),G25*H25,"") -> 800 | J25: =IF(H25="","",IF(H25>=VALUE(LEFT(MID(B25,FIND("-",B25)+1,2),2)),"✓",""))
A28: Blue cells = your inputs. Top Set Vol & Hit Top? auto-calculate.

Sheet Wk04
A1: Week 4 — Accumulation (RIR 2-3)
A3: Upper
A4: Exercise | B4: Target Reps | C4: S1 Wt | D4: S1 Reps | E4: S2 Wt | F4: S2 Reps | G4: S3 Wt | H4: S3 Reps | I4: Top Set Vol | J4: Hit Top? | K4: Notes
A5: DB Bench Press (neutral/30° incline) | B5: 8-12 | C5: 40 | D5: 10 | E5: 40 | F5: 8 | G5: 40 | H5: 9 | I5: =IF(AND(G5<>"",H5<>""),G5*H5,"") -> 360 | J5: =IF(H5="","",IF(H5>=VALUE(LEFT(MID(B5,FIND("-",B5)+1,2),2)),"✓",""))
A6: Chest-Supported DB Row | B6: 8-12 | C6: 40 | D6: 12 | E6: 40 | F6: 12 | G6: 40 | H6: 12 | I6: =IF(AND(G6<>"",H6<>""),G6*H6,"") -> 480 | J6: =IF(H6="","",IF(H6>=VALUE(LEFT(MID(B6,FIND("-",B6)+1,2),2)),"✓","")) -> ✓
A7: Seated DB Shoulder Press | B7: 8-12 | C7: 20 | D7: 15 | E7: 20 | F7: 15 | G7: 20 | H7: 15 | I7: =IF(AND(G7<>"",H7<>""),G7*H7,"") -> 300 | J7: =IF(H7="","",IF(H7>=VALUE(LEFT(MID(B7,FIND("-",B7)+1,2),2)),"✓","")) -> ✓
A8: DB Lateral Raise | B8: 12-15 | C8: 15 | D8: 15 | E8: 15 | F8: 15 | G8: 15 | H8: 15 | I8: =IF(AND(G8<>"",H8<>""),G8*H8,"") -> 225 | J8: =IF(H8="","",IF(H8>=VALUE(LEFT(MID(B8,FIND("-",B8)+1,2),2)),"✓","")) -> ✓
A9: DB Hammer Curl + OH Triceps Ext (SS) | B9: 12-15 | C9: 25 | D9: 12 | E9: 25 | F9: 12 | G9: 25 | H9: 12 | I9: =IF(AND(G9<>"",H9<>""),G9*H9,"") -> 300 | J9: =IF(H9="","",IF(H9>=VALUE(LEFT(MID(B9,FIND("-",B9)+1,2),2)),"✓",""))
B10: 12-15 | C10: 40 | D10: 15 | E10: 40 | F10: 15 | G10: 40 | H10: 15 | I10: =IF(AND(G10<>"",H10<>""),G10*H10,"") -> 600 | J10: =IF(H10="","",IF(H10>=VALUE(LEFT(MID(B10,FIND("-",B10)+1,2),2)),"✓","")) -> ✓
A11: Lower
A12: Exercise | B12: Target Reps | C12: S1 Wt | D12: S1 Reps | E12: S2 Wt | F12: S2 Reps | G12: S3 Wt | H12: S3 Reps | I12: Top Set Vol | J12: Hit Top? | K12: Notes
A13: Box squat | B13: 8-12 | C13: 115 | D13: 12 | E13: 120 | F13: 12 | G13: 120 | H13: 12 | I13: =IF(AND(G13<>"",H13<>""),G13*H13,"") -> 1440 | J13: =IF(H13="","",IF(H13>=VALUE(LEFT(MID(B13,FIND("-",B13)+1,2),2)),"✓","")) -> ✓
A14: Lying / Seated Leg Curl | B14: 8-12 | C14: 100 | D14: 12 | E14: 100 | F14: 10 | G14: 100 | I14: =IF(AND(G14<>"",H14<>""),G14*H14,"") | J14: =IF(H14="","",IF(H14>=VALUE(LEFT(MID(B14,FIND("-",B14)+1,2),2)),"✓",""))
A15: Smith Bulgarian Split Squat | B15: 8-12 / leg | C15: 20 | D15: 12 | E15: 20 | F15: 12 | G15: 20 | H15: 12 | I15: =IF(AND(G15<>"",H15<>""),G15*H15,"") -> 240 | J15: =IF(H15="","",IF(H15>=VALUE(LEFT(MID(B15,FIND("-",B15)+1,2),2)),"✓","")) -> ✓
A16: DB Hip Thrust | B16: 12-15 | C16: 135 | D16: 13 | E16: 135 | F16: 12 | G16: 135 | H16: 15 | I16: =IF(AND(G16<>"",H16<>""),G16*H16,"") -> 2025 | J16: =IF(H16="","",IF(H16>=VALUE(LEFT(MID(B16,FIND("-",B16)+1,2),2)),"✓","")) -> ✓
A17: Leg Extension + Standing Calf Raise (SS) | B17: 12-15 / 12-15 | C17: 100 | D17: 12 | E17: 100 | F17: 12 | G17: 110 | H17: 12 | I17: =IF(AND(G17<>"",H17<>""),G17*H17,"") -> 1320 | J17: =IF(H17="","",IF(H17>=VALUE(LEFT(MID(B17,FIND("-",B17)+1,2),2)),"✓",""))
B18: 12-15 / 12-15 | C18: 60 | D18: 15 | E18: 60 | G18: 60 | I18: =IF(AND(G18<>"",H18<>""),G18*H18,"") | J18: =IF(H18="","",IF(H18>=VALUE(LEFT(MID(B18,FIND("-",B18)+1,2),2)),"✓",""))
A19: Full Body
A20: Exercise | B20: Target Reps | C20: S1 Wt | D20: S1 Reps | E20: S2 Wt | F20: S2 Reps | G20: S3 Wt | H20: S3 Reps | I20: Top Set Vol | J20: Hit Top? | K20: Notes
A21: Barbell deadlift | B21: 8-12 | C21: 125 | D21: 12 | E21: 125 | F21: 12 | G21: 130 | H21: 12 | I21: =IF(AND(G21<>"",H21<>""),G21*H21,"") -> 1560 | J21: =IF(H21="","",IF(H21>=VALUE(LEFT(MID(B21,FIND("-",B21)+1,2),2)),"✓","")) -> ✓
A22: Push-Up | B22: 8-12 | C22: 135 | D22: 12 | E22: 135 | F22: 12 | G22: 135 | H22: 12 | I22: =IF(AND(G22<>"",H22<>""),G22*H22,"") -> 1620 | J22: =IF(H22="","",IF(H22>=VALUE(LEFT(MID(B22,FIND("-",B22)+1,2),2)),"✓","")) -> ✓
A23: One-Arm DB Row | B23: 8-12 / side | C23: 60 | D23: 12 | E23: 60 | F23: 12 | G23: 60 | H23: 12 | I23: =IF(AND(G23<>"",H23<>""),G23*H23,"") -> 720 | J23: =IF(H23="","",IF(H23>=VALUE(LEFT(MID(B23,FIND("-",B23)+1,2),2)),"✓","")) -> ✓
A24: DB Reverse Lunge | B24: 12-15 / leg | C24: 60 | D24: 12 | E24: 50 | F24: 12 | G24: 50 | H24: 12 | I24: =IF(AND(G24<>"",H24<>""),G24*H24,"") -> 600 | J24: =IF(H24="","",IF(H24>=VALUE(LEFT(MID(B24,FIND("-",B24)+1,2),2)),"✓",""))
A25: Pull-Up / Lat Pulldown | B25: 8-12 | C25: 100 | D25: 12 | E25: 100 | F25: 12 | G25: 100 | H25: 12 | I25: =IF(AND(G25<>"",H25<>""),G25*H25,"") -> 1200 | J25: =IF(H25="","",IF(H25>=VALUE(LEFT(MID(B25,FIND("-",B25)+1,2),2)),"✓","")) -> ✓
A28: Blue cells = your inputs. Top Set Vol & Hit Top? auto-calculate.

Sheet Wk05
A1: Week 5 — Intensification (RIR 1-2)
A3: Upper
A4: Exercise | B4: Target Reps | C4: S1 Wt | D4: S1 Reps | E4: S2 Wt | F4: S2 Reps | G4: S3 Wt | H4: S3 Reps | I4: Top Set Vol | J4: Hit Top? | K4: Notes
A5: DB Bench Press (neutral/30° incline) | B5: 8-12 | C5: 40 | D5: 13 | E5: 45 | F5: 11 | G5: 45 | H5: 8 | I5: =IF(AND(G5<>"",H5<>""),G5*H5,"") -> 360 | J5: =IF(H5="","",IF(H5>=VALUE(LEFT(MID(B5,FIND("-",B5)+1,2),2)),"✓",""))
A6: Chest-Supported DB Row | B6: 8-12 | C6: 40 | D6: 12 | E6: 45 | F6: 12 | G6: 45 | H6: 11 | I6: =IF(AND(G6<>"",H6<>""),G6*H6,"") -> 495 | J6: =IF(H6="","",IF(H6>=VALUE(LEFT(MID(B6,FIND("-",B6)+1,2),2)),"✓",""))
A7: Seated DB Shoulder Press | B7: 8-12 | C7: 20 | D7: 15 | E7: 25 | F7: 12 | G7: 25 | H7: 12 | I7: =IF(AND(G7<>"",H7<>""),G7*H7,"") -> 300 | J7: =IF(H7="","",IF(H7>=VALUE(LEFT(MID(B7,FIND("-",B7)+1,2),2)),"✓","")) -> ✓
A8: DB Lateral Raise | B8: 12-15 | C8: 15 | D8: 15 | E8: 15 | F8: 15 | G8: 15 | H8: 15 | I8: =IF(AND(G8<>"",H8<>""),G8*H8,"") -> 225 | J8: =IF(H8="","",IF(H8>=VALUE(LEFT(MID(B8,FIND("-",B8)+1,2),2)),"✓","")) -> ✓
A9: DB Hammer Curl + OH Triceps Ext (SS) | B9: 12-15 | C9: 25 | D9: 15 | E9: 25 | F9: 15 | G9: 25 | I9: =IF(AND(G9<>"",H9<>""),G9*H9,"") | J9: =IF(H9="","",IF(H9>=VALUE(LEFT(MID(B9,FIND("-",B9)+1,2),2)),"✓",""))
B10: 12-15 | C10: 45 | D10: 14 | E10: 45 | F10: 12 | G10: 45 | I10: =IF(AND(G10<>"",H10<>""),G10*H10,"") | J10: =IF(H10="","",IF(H10>=VALUE(LEFT(MID(B10,FIND("-",B10)+1,2),2)),"✓",""))
A11: Lower
A12: Exercise | B12: Target Reps | C12: S1 Wt | D12: S1 Reps | E12: S2 Wt | F12: S2 Reps | G12: S3 Wt | H12: S3 Reps | I12: Top Set Vol | J12: Hit Top? | K12: Notes
A13: Box squat | B13: 8-12 | C13: 125 | D13: 10 | E13: 125 | F13: 11 | G13: 125 | H13: 12 | I13: =IF(AND(G13<>"",H13<>""),G13*H13,"") -> 1500 | J13: =IF(H13="","",IF(H13>=VALUE(LEFT(MID(B13,FIND("-",B13)+1,2),2)),"✓","")) -> ✓
A14: Lying / Seated Leg Curl | B14: 8-12 | C14: 100 | D14: 12 | E14: 110 | F14: 8 | G14: 110 | H14: 5 | I14: =IF(AND(G14<>"",H14<>""),G14*H14,"") -> 550 | J14: =IF(H14="","",IF(H14>=VALUE(LEFT(MID(B14,FIND("-",B14)+1,2),2)),"✓",""))
A15: Smith Bulgarian Split Squat | B15: 8-12 / leg | C15: 20 | D15: 12 | E15: 25 | F15: 12 | G15: 25 | H15: 12 | I15: =IF(AND(G15<>"",H15<>""),G15*H15,"") -> 300 | J15: =IF(H15="","",IF(H15>=VALUE(LEFT(MID(B15,FIND("-",B15)+1,2),2)),"✓","")) -> ✓
A16: DB Hip Thrust | B16: 12-15 | C16: 135 | D16: 14 | E16: 135 | F16: 13 | G16: 135 | H16: 13 | I16: =IF(AND(G16<>"",H16<>""),G16*H16,"") -> 1755 | J16: =IF(H16="","",IF(H16>=VALUE(LEFT(MID(B16,FIND("-",B16)+1,2),2)),"✓",""))
A17: Leg Extension + Standing Calf Raise (SS) | B17: 12-15 / 12-15 | C17: 110 | D17: 12 | E17: 110 | F17: 12 | G17: 110 | H17: 13 | I17: =IF(AND(G17<>"",H17<>""),G17*H17,"") -> 1430 | J17: =IF(H17="","",IF(H17>=VALUE(LEFT(MID(B17,FIND("-",B17)+1,2),2)),"✓",""))
B18: 12-15 / 12-15 | C18: 70 | D18: 15 | E18: 70 | F18: 15 | G18: 70 | H18: 15 | I18: =IF(AND(G18<>"",H18<>""),G18*H18,"") -> 1050 | J18: =IF(H18="","",IF(H18>=VALUE(LEFT(MID(B18,FIND("-",B18)+1,2),2)),"✓","")) -> ✓
A19: Full Body
A20: Exercise | B20: Target Reps | C20: S1 Wt | D20: S1 Reps | E20: S2 Wt | F20: S2 Reps | G20: S3 Wt | H20: S3 Reps | I20: Top Set Vol | J20: Hit Top? | K20: Notes
A21: 45° Back Extension | B21: 8-12 | C21: 15 | D21: 13 | E21: 15 | F21: 12 | G21: 15 | H21: 13 | I21: =IF(AND(G21<>"",H21<>""),G21*H21,"") -> 195 | J21: =IF(H21="","",IF(H21>=VALUE(LEFT(MID(B21,FIND("-",B21)+1,2),2)),"✓","")) -> ✓
A22: Push-Up | B22: 8-12 | C22: 135 | D22: 20 | E22: 135 | F22: 15 | G22: 135 | H22: 12 | I22: =IF(AND(G22<>"",H22<>""),G22*H22,"") -> 1620 | J22: =IF(H22="","",IF(H22>=VALUE(LEFT(MID(B22,FIND("-",B22)+1,2),2)),"✓","")) -> ✓
A23: One-Arm DB Row | B23: 8-12 / side | C23: 60 | D23: 12 | E23: 70 | F23: 8 | G23: 70 | H23: 8 | I23: =IF(AND(G23<>"",H23<>""),G23*H23,"") -> 560 | J23: =IF(H23="","",IF(H23>=VALUE(LEFT(MID(B23,FIND("-",B23)+1,2),2)),"✓",""))
A24: DB Reverse Lunge | B24: 12-15 / leg | C24: 50 | D24: 15 | E24: 50 | F24: 15 | G24: 50 | H24: 9 | I24: =IF(AND(G24<>"",H24<>""),G24*H24,"") -> 450 | J24: =IF(H24="","",IF(H24>=VALUE(LEFT(MID(B24,FIND("-",B24)+1,2),2)),"✓",""))
A25: Pull-Up / Lat Pulldown | B25: 8-12 | C25: 100 | D25: 12 | E25: 100 | F25: 8 | G25: 100 | H25: 8 | I25: =IF(AND(G25<>"",H25<>""),G25*H25,"") -> 800 | J25: =IF(H25="","",IF(H25>=VALUE(LEFT(MID(B25,FIND("-",B25)+1,2),2)),"✓",""))
A28: Blue cells = your inputs. Top Set Vol & Hit Top? auto-calculate.

Sheet Wk06
A1: Week 6 — Intensification (RIR 1-2)
A3: Upper
A4: Exercise | B4: Target Reps | C4: S1 Wt | D4: S1 Reps | E4: S2 Wt | F4: S2 Reps | G4: S3 Wt | H4: S3 Reps | I4: Top Set Vol | J4: Hit Top? | K4: Notes
A5: DB Bench Press (neutral/30° incline) | B5: 8-12 | C5: 45 | D5: 8 | E5: 45 | F5: 8 | G5: 45 | H5: 8 | I5: =IF(AND(G5<>"",H5<>""),G5*H5,"") -> 360 | J5: =IF(H5="","",IF(H5>=VALUE(LEFT(MID(B5,FIND("-",B5)+1,2),2)),"✓",""))
A6: Chest-Supported DB Row | B6: 8-12 | C6: 45 | D6: 12 | E6: 50 | F6: 8 | G6: 50 | H6: 8 | I6: =IF(AND(G6<>"",H6<>""),G6*H6,"") -> 400 | J6: =IF(H6="","",IF(H6>=VALUE(LEFT(MID(B6,FIND("-",B6)+1,2),2)),"✓",""))
A7: Seated DB Shoulder Press | B7: 8-12 | C7: 25 | D7: 12 | E7: 25 | F7: 12 | G7: 25 | H7: 12 | I7: =IF(AND(G7<>"",H7<>""),G7*H7,"") -> 300 | J7: =IF(H7="","",IF(H7>=VALUE(LEFT(MID(B7,FIND("-",B7)+1,2),2)),"✓","")) -> ✓
A8: DB Lateral Raise | B8: 12-15 | C8: 15 | D8: 15 | E8: 15 | F8: 15 | G8: 15 | H8: 15 | I8: =IF(AND(G8<>"",H8<>""),G8*H8,"") -> 225 | J8: =IF(H8="","",IF(H8>=VALUE(LEFT(MID(B8,FIND("-",B8)+1,2),2)),"✓","")) -> ✓
A9: DB Hammer Curl + OH Triceps Ext (SS) | B9: 12-15 | C9: 25 | D9: 15 | E9: 25 | F9: 12 | G9: 20 | H9: 13 | I9: =IF(AND(G9<>"",H9<>""),G9*H9,"") -> 260 | J9: =IF(H9="","",IF(H9>=VALUE(LEFT(MID(B9,FIND("-",B9)+1,2),2)),"✓",""))
B10: 12-15 | C10: 45 | D10: 15 | E10: 45 | F10: 12 | G10: 40 | H10: 12 | I10: =IF(AND(G10<>"",H10<>""),G10*H10,"") -> 480 | J10: =IF(H10="","",IF(H10>=VALUE(LEFT(MID(B10,FIND("-",B10)+1,2),2)),"✓",""))
A11: Lower
A12: Exercise | B12: Target Reps | C12: S1 Wt | D12: S1 Reps | E12: S2 Wt | F12: S2 Reps | G12: S3 Wt | H12: S3 Reps | I12: Top Set Vol | J12: Hit Top? | K12: Notes
A13: Leg press | B13: 8-12 | C13: 125 | I13: =IF(AND(G13<>"",H13<>""),G13*H13,"") | J13: =IF(H13="","",IF(H13>=VALUE(LEFT(MID(B13,FIND("-",B13)+1,2),2)),"✓",""))
A14: Lying / Seated Leg Curl | B14: 8-12 | C14: 105 | I14: =IF(AND(G14<>"",H14<>""),G14*H14,"") | J14: =IF(H14="","",IF(H14>=VALUE(LEFT(MID(B14,FIND("-",B14)+1,2),2)),"✓",""))
A15: Smith Bulgarian Split Squat | B15: 8-12 / leg | C15: 25 | I15: =IF(AND(G15<>"",H15<>""),G15*H15,"") | J15: =IF(H15="","",IF(H15>=VALUE(LEFT(MID(B15,FIND("-",B15)+1,2),2)),"✓",""))
A16: DB Hip Thrust | B16: 12-15 | C16: 135 | I16: =IF(AND(G16<>"",H16<>""),G16*H16,"") | J16: =IF(H16="","",IF(H16>=VALUE(LEFT(MID(B16,FIND("-",B16)+1,2),2)),"✓",""))
A17: Leg Extension + Standing Calf Raise (SS) | B17: 12-15 / 12-15 | C17: 110 | I17: =IF(AND(G17<>"",H17<>""),G17*H17,"") | J17: =IF(H17="","",IF(H17>=VALUE(LEFT(MID(B17,FIND("-",B17)+1,2),2)),"✓",""))
B18: 12-15 / 12-15 | C18: 70 | I18: =IF(AND(G18<>"",H18<>""),G18*H18,"") | J18: =IF(H18="","",IF(H18>=VALUE(LEFT(MID(B18,FIND("-",B18)+1,2),2)),"✓",""))
A19: Full Body
A20: Exercise | B20: Target Reps | C20: S1 Wt | D20: S1 Reps | E20: S2 Wt | F20: S2 Reps | G20: S3 Wt | H20: S3 Reps | I20: Top Set Vol | J20: Hit Top? | K20: Notes
A21: 45° Back Extension | B21: 8-12 | C21: 15 | D21: 12 | E21: 15 | F21: 12 | G21: 20 | H21: 13 | I21: =IF(AND(G21<>"",H21<>""),G21*H21,"") -> 260 | J21: =IF(H21="","",IF(H21>=VALUE(LEFT(MID(B21,FIND("-",B21)+1,2),2)),"✓","")) -> ✓
A22: DB Floor Press / Push-Up | B22: 8-12 | C22: 135 | D22: 20 | E22: 135 | F22: 15 | G22: 135 | H22: 12 | I22: =IF(AND(G22<>"",H22<>""),G22*H22,"") -> 1620 | J22: =IF(H22="","",IF(H22>=VALUE(LEFT(MID(B22,FIND("-",B22)+1,2),2)),"✓","")) -> ✓
A23: One-Arm DB Row | B23: 8-12 / side | C23: 65 | D23: 11 | E23: 65 | F23: 10 | G23: 65 | H23: 10 | I23: =IF(AND(G23<>"",H23<>""),G23*H23,"") -> 650 | J23: =IF(H23="","",IF(H23>=VALUE(LEFT(MID(B23,FIND("-",B23)+1,2),2)),"✓",""))
A24: DB Reverse Lunge | B24: 12-15 / leg | C24: 50 | D24: 12 | E24: 50 | G24: 50 | I24: =IF(AND(G24<>"",H24<>""),G24*H24,"") | J24: =IF(H24="","",IF(H24>=VALUE(LEFT(MID(B24,FIND("-",B24)+1,2),2)),"✓",""))
A25: Pull-Up / Lat Pulldown | B25: 8-12 | C25: 95 | D25: 12 | E25: 95 | F25: 10 | G25: 95 | H25: 10 | I25: =IF(AND(G25<>"",H25<>""),G25*H25,"") -> 950 | J25: =IF(H25="","",IF(H25>=VALUE(LEFT(MID(B25,FIND("-",B25)+1,2),2)),"✓",""))
A28: Blue cells = your inputs. Top Set Vol & Hit Top? auto-calculate.

Sheet Wk07
A1: Week 7 — Intensification (RIR 1-2)
A3: Upper
A4: Exercise | B4: Target Reps | C4: S1 Wt | D4: S1 Reps | E4: S2 Wt | F4: S2 Reps | G4: S3 Wt | H4: S3 Reps | I4: Top Set Vol | J4: Hit Top? | K4: Notes
A5: DB Bench Press (neutral/30° incline) | B5: 8-12 | C5: 45 | D5: 10 | E5: 45 | F5: 9 | G5: 45 | H5: 8 | I5: =IF(AND(G5<>"",H5<>""),G5*H5,"") -> 360 | J5: =IF(H5="","",IF(H5>=VALUE(LEFT(MID(B5,FIND("-",B5)+1,2),2)),"✓",""))
A6: Chest-Supported DB Row | B6: 8-12 | C6: 50 | D6: 8 | E6: 50 | F6: 10 | G6: 50 | H6: 8 | I6: =IF(AND(G6<>"",H6<>""),G6*H6,"") -> 400 | J6: =IF(H6="","",IF(H6>=VALUE(LEFT(MID(B6,FIND("-",B6)+1,2),2)),"✓",""))
A7: Seated DB Shoulder Press | B7: 8-12 | C7: 25 | D7: 12 | E7: 30 | F7: 8 | G7: 30 | H7: 8 | I7: =IF(AND(G7<>"",H7<>""),G7*H7,"") -> 240 | J7: =IF(H7="","",IF(H7>=VALUE(LEFT(MID(B7,FIND("-",B7)+1,2),2)),"✓",""))
A8: DB Lateral Raise | B8: 12-15 | C8: 15 | D8: 15 | E8: 15 | F8: 15 | G8: 15 | H8: 15 | I8: =IF(AND(G8<>"",H8<>""),G8*H8,"") -> 225 | J8: =IF(H8="","",IF(H8>=VALUE(LEFT(MID(B8,FIND("-",B8)+1,2),2)),"✓","")) -> ✓
A9: DB Hammer Curl + OH Triceps Ext (SS) | B9: 12-15 | C9: 25 | D9: 15 | E9: 25 | F9: 15 | G9: 20 | H9: 15 | I9: =IF(AND(G9<>"",H9<>""),G9*H9,"") -> 300 | J9: =IF(H9="","",IF(H9>=VALUE(LEFT(MID(B9,FIND("-",B9)+1,2),2)),"✓","")) -> ✓
B10: 12-15 | C10: 45 | D10: 15 | E10: 45 | F10: 13 | G10: 40 | H10: 15 | I10: =IF(AND(G10<>"",H10<>""),G10*H10,"") -> 600 | J10: =IF(H10="","",IF(H10>=VALUE(LEFT(MID(B10,FIND("-",B10)+1,2),2)),"✓","")) -> ✓
A11: Lower
A12: Exercise | B12: Target Reps | C12: S1 Wt | D12: S1 Reps | E12: S2 Wt | F12: S2 Reps | G12: S3 Wt | H12: S3 Reps | I12: Top Set Vol | J12: Hit Top? | K12: Notes
A13: Box squat | B13: 8-12 | C13: 115 | D13: 12 | E13: 125 | F13: 10 | G13: 125 | H13: 10 | I13: =IF(AND(G13<>"",H13<>""),G13*H13,"") -> 1250 | J13: =IF(H13="","",IF(H13>=VALUE(LEFT(MID(B13,FIND("-",B13)+1,2),2)),"✓",""))
A14: Lying / Seated Leg Curl | B14: 8-12 | C14: 105 | D14: 12 | E14: 105 | F14: 8 | G14: 100 | H14: 9 | I14: =IF(AND(G14<>"",H14<>""),G14*H14,"") -> 900 | J14: =IF(H14="","",IF(H14>=VALUE(LEFT(MID(B14,FIND("-",B14)+1,2),2)),"✓",""))
A15: Smith Bulgarian Split Squat | B15: 8-12 / leg | C15: 30 | D15: 12 | E15: 30 | F15: 12 | G15: 30 | H15: 12 | I15: =IF(AND(G15<>"",H15<>""),G15*H15,"") -> 360 | J15: =IF(H15="","",IF(H15>=VALUE(LEFT(MID(B15,FIND("-",B15)+1,2),2)),"✓","")) -> ✓
A16: Hip Thrust | B16: 12-15 | C16: 135 | D16: 13 | E16: 135 | F16: 12 | G16: 135 | H16: 15 | I16: =IF(AND(G16<>"",H16<>""),G16*H16,"") -> 2025 | J16: =IF(H16="","",IF(H16>=VALUE(LEFT(MID(B16,FIND("-",B16)+1,2),2)),"✓","")) -> ✓
A17: Leg Extension + Standing Calf Raise (SS) | B17: 12-15 / 12-15 | C17: 110 | D17: 13 | E17: 110 | F17: 13 | G17: 110 | H17: 13 | I17: =IF(AND(G17<>"",H17<>""),G17*H17,"") -> 1430 | J17: =IF(H17="","",IF(H17>=VALUE(LEFT(MID(B17,FIND("-",B17)+1,2),2)),"✓",""))
B18: 12-15 / 12-15 | C18: 70 | D18: 15 | E18: 70 | F18: 15 | G18: 70 | H18: 15 | I18: =IF(AND(G18<>"",H18<>""),G18*H18,"") -> 1050 | J18: =IF(H18="","",IF(H18>=VALUE(LEFT(MID(B18,FIND("-",B18)+1,2),2)),"✓","")) -> ✓
A19: Full Body
A20: Exercise | B20: Target Reps | C20: S1 Wt | D20: S1 Reps | E20: S2 Wt | F20: S2 Reps | G20: S3 Wt | H20: S3 Reps | I20: Top Set Vol | J20: Hit Top? | K20: Notes
A21: 45° Back Extension | B21: 8-12 | C21: 15 | D21: 12 | E21: 15 | F21: 12 | G21: 15 | H21: 12 | I21: =IF(AND(G21<>"",H21<>""),G21*H21,"") -> 180 | J21: =IF(H21="","",IF(H21>=VALUE(LEFT(MID(B21,FIND("-",B21)+1,2),2)),"✓","")) -> ✓
A22: DB Floor Press / Push-Up | B22: 8-12 | C22: 135 | D22: 20 | E22: 135 | F22: 15 | G22: 135 | H22: 13 | I22: =IF(AND(G22<>"",H22<>""),G22*H22,"") -> 1755 | J22: =IF(H22="","",IF(H22>=VALUE(LEFT(MID(B22,FIND("-",B22)+1,2),2)),"✓","")) -> ✓
A23: One-Arm DB Row | B23: 8-12 / side | C23: 65 | D23: 12 | E23: 65 | F23: 11 | G23: 65 | H23: 11 | I23: =IF(AND(G23<>"",H23<>""),G23*H23,"") -> 715 | J23: =IF(H23="","",IF(H23>=VALUE(LEFT(MID(B23,FIND("-",B23)+1,2),2)),"✓",""))
A24: DB Reverse Lunge | B24: 12-15 / leg | C24: 50 | D24: 12 | E24: 50 | F24: 12 | G24: 50 | H24: 12 | I24: =IF(AND(G24<>"",H24<>""),G24*H24,"") -> 600 | J24: =IF(H24="","",IF(H24>=VALUE(LEFT(MID(B24,FIND("-",B24)+1,2),2)),"✓",""))
A25: Pull-Up / Lat Pulldown | B25: 8-12 | C25: 100 | D25: 12 | E25: 105 | F25: 11 | G25: 110 | H25: 8 | I25: =IF(AND(G25<>"",H25<>""),G25*H25,"") -> 880 | J25: =IF(H25="","",IF(H25>=VALUE(LEFT(MID(B25,FIND("-",B25)+1,2),2)),"✓",""))
A28: Blue cells = your inputs. Top Set Vol & Hit Top? auto-calculate.

Sheet Wk08
A1: Week 8 — Intensification (RIR 1-2)
A3: Upper
A4: Exercise | B4: Target Reps | C4: S1 Wt | D4: S1 Reps | E4: S2 Wt | F4: S2 Reps | G4: S3 Wt | H4: S3 Reps | I4: Top Set Vol | J4: Hit Top? | K4: Notes
A5: DB Bench Press (neutral/30° incline) | B5: 8-12 | C5: 45 | D5: 10 | E5: 45 | F5: 8 | G5: 45 | H5: 9 | I5: =IF(AND(G5<>"",H5<>""),G5*H5,"") -> 405 | J5: =IF(H5="","",IF(H5>=VALUE(LEFT(MID(B5,FIND("-",B5)+1,2),2)),"✓",""))
A6: Chest-Supported DB Row | B6: 8-12 | C6: 45 | D6: 12 | E6: 50 | F6: 9 | G6: 50 | H6: 8 | I6: =IF(AND(G6<>"",H6<>""),G6*H6,"") -> 400 | J6: =IF(H6="","",IF(H6>=VALUE(LEFT(MID(B6,FIND("-",B6)+1,2),2)),"✓",""))
A7: Seated DB Shoulder Press | B7: 8-12 | C7: 30 | D7: 12 | E7: 30 | F7: 11 | G7: 30 | H7: 9 | I7: =IF(AND(G7<>"",H7<>""),G7*H7,"") -> 270 | J7: =IF(H7="","",IF(H7>=VALUE(LEFT(MID(B7,FIND("-",B7)+1,2),2)),"✓",""))
A8: DB Lateral Raise | B8: 12-15 | C8: 10 | D8: 15 | E8: 10 | F8: 15 | G8: 10 | H8: 15 | I8: =IF(AND(G8<>"",H8<>""),G8*H8,"") -> 150 | J8: =IF(H8="","",IF(H8>=VALUE(LEFT(MID(B8,FIND("-",B8)+1,2),2)),"✓","")) -> ✓
A9: DB Hammer Curl + OH Triceps Ext (SS) | B9: 12-15 | C9: 25 | D9: 13 | E9: 25 | F9: 15 | G9: 25 | H9: 12 | I9: =IF(AND(G9<>"",H9<>""),G9*H9,"") -> 300 | J9: =IF(H9="","",IF(H9>=VALUE(LEFT(MID(B9,FIND("-",B9)+1,2),2)),"✓",""))
B10: 12-15 | C10: 45 | D10: 14 | E10: 45 | F10: 13 | G10: 45 | H10: 12 | I10: =IF(AND(G10<>"",H10<>""),G10*H10,"") -> 540 | J10: =IF(H10="","",IF(H10>=VALUE(LEFT(MID(B10,FIND("-",B10)+1,2),2)),"✓",""))
A11: Lower
A12: Exercise | B12: Target Reps | C12: S1 Wt | D12: S1 Reps | E12: S2 Wt | F12: S2 Reps | G12: S3 Wt | H12: S3 Reps | I12: Top Set Vol | J12: Hit Top? | K12: Notes
A13: Box squat | B13: 8-12 | C13: 125 | D13: 12 | E13: 130 | F13: 12 | G13: 135 | H13: 10 | I13: =IF(AND(G13<>"",H13<>""),G13*H13,"") -> 1350 | J13: =IF(H13="","",IF(H13>=VALUE(LEFT(MID(B13,FIND("-",B13)+1,2),2)),"✓",""))
A14: Lying / Seated Leg Curl | B14: 8-12 | C14: 95 | D14: 12 | E14: 100 | F14: 10 | G14: 100 | H14: 11 | I14: =IF(AND(G14<>"",H14<>""),G14*H14,"") -> 1100 | J14: =IF(H14="","",IF(H14>=VALUE(LEFT(MID(B14,FIND("-",B14)+1,2),2)),"✓",""))
A15: Smith Bulgarian Split Squat | B15: 8-12 / leg | C15: 30 | D15: 12 | E15: 30 | F15: 12 | G15: 35 | H15: 8 | I15: =IF(AND(G15<>"",H15<>""),G15*H15,"") -> 280 | J15: =IF(H15="","",IF(H15>=VALUE(LEFT(MID(B15,FIND("-",B15)+1,2),2)),"✓",""))
A16: DB Hip Thrust | B16: 12-15 | C16: 135 | D16: 15 | E16: 135 | F16: 15 | G16: 140 | H16: 15 | I16: =IF(AND(G16<>"",H16<>""),G16*H16,"") -> 2100 | J16: =IF(H16="","",IF(H16>=VALUE(LEFT(MID(B16,FIND("-",B16)+1,2),2)),"✓","")) -> ✓
A17: Leg Extension + Standing Calf Raise (SS) | B17: 12-15 / 12-15 | C17: 110 | D17: 15 | E17: 110 | F17: 15 | G17: 115 | H17: 13 | I17: =IF(AND(G17<>"",H17<>""),G17*H17,"") -> 1495 | J17: =IF(H17="","",IF(H17>=VALUE(LEFT(MID(B17,FIND("-",B17)+1,2),2)),"✓",""))
B18: 12-15 / 12-15 | C18: 70 | D18: 15 | E18: 70 | F18: 15 | G18: 75 | H18: 15 | I18: =IF(AND(G18<>"",H18<>""),G18*H18,"") -> 1125 | J18: =IF(H18="","",IF(H18>=VALUE(LEFT(MID(B18,FIND("-",B18)+1,2),2)),"✓","")) -> ✓
A19: Full Body
A20: Exercise | B20: Target Reps | C20: S1 Wt | D20: S1 Reps | E20: S2 Wt | F20: S2 Reps | G20: S3 Wt | H20: S3 Reps | I20: Top Set Vol | J20: Hit Top? | K20: Notes
A21: 45° Back Extension | B21: 8-12 | C21: 15 | D21: 20 | E21: 20 | F21: 20 | G21: 20 | H21: 20 | I21: =IF(AND(G21<>"",H21<>""),G21*H21,"") -> 400 | J21: =IF(H21="","",IF(H21>=VALUE(LEFT(MID(B21,FIND("-",B21)+1,2),2)),"✓","")) -> ✓
A22: DB Floor Press / Push-Up | B22: 8-12 | C22: 135 | D22: 22 | E22: 135 | F22: 17 | G22: 135 | H22: 10 | I22: =IF(AND(G22<>"",H22<>""),G22*H22,"") -> 1350 | J22: =IF(H22="","",IF(H22>=VALUE(LEFT(MID(B22,FIND("-",B22)+1,2),2)),"✓",""))
A23: One-Arm DB Row | B23: 8-12 / side | C23: 65 | D23: 12 | E23: 65 | F23: 10 | G23: 65 | H23: 10 | I23: =IF(AND(G23<>"",H23<>""),G23*H23,"") -> 650 | J23: =IF(H23="","",IF(H23>=VALUE(LEFT(MID(B23,FIND("-",B23)+1,2),2)),"✓",""))
A24: DB Reverse Lunge | B24: 12-15 / leg | C24: 50 | D24: 15 | E24: 50 | F24: 15 | G24: 50 | H24: 15 | I24: =IF(AND(G24<>"",H24<>""),G24*H24,"") -> 750 | J24: =IF(H24="","",IF(H24>=VALUE(LEFT(MID(B24,FIND("-",B24)+1,2),2)),"✓","")) -> ✓
A25: Pull-Up / Lat Pulldown | B25: 8-12 | C25: 110 | D25: 12 | E25: 110 | F25: 10 | G25: 110 | H25: 8 | I25: =IF(AND(G25<>"",H25<>""),G25*H25,"") -> 880 | J25: =IF(H25="","",IF(H25>=VALUE(LEFT(MID(B25,FIND("-",B25)+1,2),2)),"✓",""))
A28: Blue cells = your inputs. Top Set Vol & Hit Top? auto-calculate.

Sheet Wk09
A1: Week 9 — Peak (RIR 0-1)
A3: Upper
A4: Exercise | B4: Target Reps | C4: S1 Wt | D4: S1 Reps | E4: S2 Wt | F4: S2 Reps | G4: S3 Wt | H4: S3 Reps | I4: Top Set Vol | J4: Hit Top? | K4: Notes
A5: DB Bench Press (neutral/30° incline) | B5: 8-12 | C5: 45 | D5: 9 | E5: 45 | F5: 9 | G5: 45 | H5: 8 | I5: =IF(AND(G5<>"",H5<>""),G5*H5,"") -> 360 | J5: =IF(H5="","",IF(H5>=VALUE(LEFT(MID(B5,FIND("-",B5)+1,2),2)),"✓",""))
A6: Chest-Supported DB Row | B6: 8-12 | C6: 45 | D6: 12 | E6: 45 | F6: 10 | G6: 45 | H6: 9 | I6: =IF(AND(G6<>"",H6<>""),G6*H6,"") -> 405 | J6: =IF(H6="","",IF(H6>=VALUE(LEFT(MID(B6,FIND("-",B6)+1,2),2)),"✓",""))
A7: Seated DB Shoulder Press | B7: 8-12 | C7: 30 | D7: 12 | E7: 30 | F7: 12 | G7: 30 | H7: 8 | I7: =IF(AND(G7<>"",H7<>""),G7*H7,"") -> 240 | J7: =IF(H7="","",IF(H7>=VALUE(LEFT(MID(B7,FIND("-",B7)+1,2),2)),"✓",""))
A8: DB Lateral Raise | B8: 12-15 | C8: 10 | D8: 12 | E8: 10 | F8: 12 | G8: 10 | H8: 12 | I8: =IF(AND(G8<>"",H8<>""),G8*H8,"") -> 120 | J8: =IF(H8="","",IF(H8>=VALUE(LEFT(MID(B8,FIND("-",B8)+1,2),2)),"✓",""))
A9: DB Hammer Curl + OH Triceps Ext (SS) | B9: 12-15 | C9: 25 | D9: 15 | E9: 25 | F9: 14 | G9: 25 | H9: 12 | I9: =IF(AND(G9<>"",H9<>""),G9*H9,"") -> 300 | J9: =IF(H9="","",IF(H9>=VALUE(LEFT(MID(B9,FIND("-",B9)+1,2),2)),"✓",""))
B10: 12-15 | C10: 45 | D10: 15 | E10: 45 | F10: 13 | G10: 45 | H10: 13 | I10: =IF(AND(G10<>"",H10<>""),G10*H10,"") -> 585 | J10: =IF(H10="","",IF(H10>=VALUE(LEFT(MID(B10,FIND("-",B10)+1,2),2)),"✓",""))
A11: Lower
A12: Exercise | B12: Target Reps | C12: S1 Wt | D12: S1 Reps | E12: S2 Wt | F12: S2 Reps | G12: S3 Wt | H12: S3 Reps | I12: Top Set Vol | J12: Hit Top? | K12: Notes
A13: Box squat | B13: 8-12 | C13: 135 | D13: 12 | E13: 135 | F13: 12 | G13: 140 | H13: 9 | I13: =IF(AND(G13<>"",H13<>""),G13*H13,"") -> 1260 | J13: =IF(H13="","",IF(H13>=VALUE(LEFT(MID(B13,FIND("-",B13)+1,2),2)),"✓",""))
A14: Lying / Seated Leg Curl | B14: 8-12 | C14: 95 | D14: 12 | E14: 100 | F14: 11 | G14: 105 | H14: 8 | I14: =IF(AND(G14<>"",H14<>""),G14*H14,"") -> 840 | J14: =IF(H14="","",IF(H14>=VALUE(LEFT(MID(B14,FIND("-",B14)+1,2),2)),"✓",""))
A15: Smith Bulgarian Split Squat | B15: 8-12 / leg | C15: 35 | D15: 12 | E15: 35 | F15: 12 | G15: 40 | H15: 12 | I15: =IF(AND(G15<>"",H15<>""),G15*H15,"") -> 480 | J15: =IF(H15="","",IF(H15>=VALUE(LEFT(MID(B15,FIND("-",B15)+1,2),2)),"✓","")) -> ✓
A16: DB Hip Thrust | B16: 12-15 | C16: 140 | D16: 14 | E16: 140 | F16: 14 | G16: 140 | H16: 13 | I16: =IF(AND(G16<>"",H16<>""),G16*H16,"") -> 1820 | J16: =IF(H16="","",IF(H16>=VALUE(LEFT(MID(B16,FIND("-",B16)+1,2),2)),"✓",""))
A17: Leg Extension + Standing Calf Raise (SS) | B17: 12-15 / 12-15 | C17: 115 | D17: 15 | E17: 115 | F17: 15 | G17: 115 | H17: 15 | I17: =IF(AND(G17<>"",H17<>""),G17*H17,"") -> 1725 | J17: =IF(H17="","",IF(H17>=VALUE(LEFT(MID(B17,FIND("-",B17)+1,2),2)),"✓","")) -> ✓
B18: 12-15 / 12-15 | C18: 75 | D18: 15 | E18: 75 | F18: 15 | G18: 75 | H18: 15 | I18: =IF(AND(G18<>"",H18<>""),G18*H18,"") -> 1125 | J18: =IF(H18="","",IF(H18>=VALUE(LEFT(MID(B18,FIND("-",B18)+1,2),2)),"✓","")) -> ✓
A19: Full Body
A20: Exercise | B20: Target Reps | C20: S1 Wt | D20: S1 Reps | E20: S2 Wt | F20: S2 Reps | G20: S3 Wt | H20: S3 Reps | I20: Top Set Vol | J20: Hit Top? | K20: Notes
A21: 45° Back Extension | B21: 8-12 | C21: 20 | D21: 20 | E21: 20 | F21: 20 | G21: 20 | H21: 20 | I21: =IF(AND(G21<>"",H21<>""),G21*H21,"") -> 400 | J21: =IF(H21="","",IF(H21>=VALUE(LEFT(MID(B21,FIND("-",B21)+1,2),2)),"✓","")) -> ✓
A22: DB Floor Press / Push-Up | B22: 8-12 | C22: 135 | D22: 24 | E22: 135 | F22: 16 | G22: 135 | H22: 13 | I22: =IF(AND(G22<>"",H22<>""),G22*H22,"") -> 1755 | J22: =IF(H22="","",IF(H22>=VALUE(LEFT(MID(B22,FIND("-",B22)+1,2),2)),"✓","")) -> ✓
A23: One-Arm DB Row | B23: 8-12 / side | C23: 65 | D23: 12 | E23: 65 | F23: 12 | G23: 65 | H23: 11 | I23: =IF(AND(G23<>"",H23<>""),G23*H23,"") -> 715 | J23: =IF(H23="","",IF(H23>=VALUE(LEFT(MID(B23,FIND("-",B23)+1,2),2)),"✓",""))
A24: DB Reverse Lunge | B24: 12-15 / leg | C24: 50 | I24: =IF(AND(G24<>"",H24<>""),G24*H24,"") | J24: =IF(H24="","",IF(H24>=VALUE(LEFT(MID(B24,FIND("-",B24)+1,2),2)),"✓",""))
A25: Pull-Up / Lat Pulldown | B25: 8-12 | C25: 110 | D25: 12 | E25: 110 | F25: 12 | G25: 110 | H25: 8 | I25: =IF(AND(G25<>"",H25<>""),G25*H25,"") -> 880 | J25: =IF(H25="","",IF(H25>=VALUE(LEFT(MID(B25,FIND("-",B25)+1,2),2)),"✓",""))
A28: Blue cells = your inputs. Top Set Vol & Hit Top? auto-calculate.

Sheet Wk10
A1: Week 10 — Peak (RIR 0-1)
A3: Upper
A4: Exercise | B4: Target Reps | C4: S1 Wt | D4: S1 Reps | E4: S2 Wt | F4: S2 Reps | G4: S3 Wt | H4: S3 Reps | I4: Top Set Vol | J4: Hit Top? | K4: Notes
A5: DB Bench Press (neutral/30° incline) | B5: 8-12 | C5: 45 | D5: 11 | E5: 45 | F5: 10 | G5: 45 | H5: 8 | I5: =IF(AND(G5<>"",H5<>""),G5*H5,"") -> 360 | J5: =IF(H5="","",IF(H5>=VALUE(LEFT(MID(B5,FIND("-",B5)+1,2),2)),"✓",""))
A6: Chest-Supported DB Row | B6: 8-12 | C6: 45 | D6: 12 | E6: 45 | F6: 12 | G6: 50 | H6: 8 | I6: =IF(AND(G6<>"",H6<>""),G6*H6,"") -> 400 | J6: =IF(H6="","",IF(H6>=VALUE(LEFT(MID(B6,FIND("-",B6)+1,2),2)),"✓",""))
A7: Seated DB Shoulder Press | B7: 8-12 | C7: 30 | D7: 15 | E7: 30 | F7: 13 | G7: 30 | H7: 12 | I7: =IF(AND(G7<>"",H7<>""),G7*H7,"") -> 360 | J7: =IF(H7="","",IF(H7>=VALUE(LEFT(MID(B7,FIND("-",B7)+1,2),2)),"✓","")) -> ✓
A8: DB Lateral Raise | B8: 12-15 | C8: 10 | D8: 15 | E8: 15 | F8: 14 | G8: 15 | H8: 12 | I8: =IF(AND(G8<>"",H8<>""),G8*H8,"") -> 180 | J8: =IF(H8="","",IF(H8>=VALUE(LEFT(MID(B8,FIND("-",B8)+1,2),2)),"✓",""))
A9: DB Hammer Curl + OH Triceps Ext (SS) | B9: 12-15 | C9: 25 | D9: 15 | E9: 25 | F9: 15 | G9: 25 | H9: 12 | I9: =IF(AND(G9<>"",H9<>""),G9*H9,"") -> 300 | J9: =IF(H9="","",IF(H9>=VALUE(LEFT(MID(B9,FIND("-",B9)+1,2),2)),"✓",""))
B10: 12-15 | C10: 45 | D10: 15 | E10: 45 | F10: 15 | G10: 45 | H10: 14 | I10: =IF(AND(G10<>"",H10<>""),G10*H10,"") -> 630 | J10: =IF(H10="","",IF(H10>=VALUE(LEFT(MID(B10,FIND("-",B10)+1,2),2)),"✓",""))
A11: Lower
A12: Exercise | B12: Target Reps | C12: S1 Wt | D12: S1 Reps | E12: S2 Wt | F12: S2 Reps | G12: S3 Wt | H12: S3 Reps | I12: Top Set Vol | J12: Hit Top? | K12: Notes
A13: Box squat | B13: 8-12 | C13: 140 | D13: 10 | E13: 140 | F13: 12 | G13: 140 | H13: 9 | I13: =IF(AND(G13<>"",H13<>""),G13*H13,"") -> 1260 | J13: =IF(H13="","",IF(H13>=VALUE(LEFT(MID(B13,FIND("-",B13)+1,2),2)),"✓",""))
A14: Lying / Seated Leg Curl | B14: 8-12 | C14: 105 | D14: 12 | E14: 110 | F14: 8 | G14: 110 | H14: 8 | I14: =IF(AND(G14<>"",H14<>""),G14*H14,"") -> 880 | J14: =IF(H14="","",IF(H14>=VALUE(LEFT(MID(B14,FIND("-",B14)+1,2),2)),"✓",""))
A15: Smith Bulgarian Split Squat | B15: 8-12 / leg | C15: 40 | D15: 12 | E15: 40 | F15: 12 | G15: 40 | H15: 12 | I15: =IF(AND(G15<>"",H15<>""),G15*H15,"") -> 480 | J15: =IF(H15="","",IF(H15>=VALUE(LEFT(MID(B15,FIND("-",B15)+1,2),2)),"✓","")) -> ✓
A16: DB Hip Thrust | B16: 12-15 | C16: 140 | D16: 15 | E16: 145 | F16: 13 | G16: 145 | H16: 13 | I16: =IF(AND(G16<>"",H16<>""),G16*H16,"") -> 1885 | J16: =IF(H16="","",IF(H16>=VALUE(LEFT(MID(B16,FIND("-",B16)+1,2),2)),"✓",""))
A17: Leg Extension + Standing Calf Raise (SS) | B17: 12-15 / 12-15 | C17: 115 | D17: 15 | E17: 120 | F17: 12 | G17: 120 | H17: 15 | I17: =IF(AND(G17<>"",H17<>""),G17*H17,"") -> 1800 | J17: =IF(H17="","",IF(H17>=VALUE(LEFT(MID(B17,FIND("-",B17)+1,2),2)),"✓","")) -> ✓
B18: 12-15 / 12-15 | C18: 75 | D18: 15 | E18: 80 | F18: 15 | G18: 80 | H18: 15 | I18: =IF(AND(G18<>"",H18<>""),G18*H18,"") -> 1200 | J18: =IF(H18="","",IF(H18>=VALUE(LEFT(MID(B18,FIND("-",B18)+1,2),2)),"✓","")) -> ✓
A19: Full Body
A20: Exercise | B20: Target Reps | C20: S1 Wt | D20: S1 Reps | E20: S2 Wt | F20: S2 Reps | G20: S3 Wt | H20: S3 Reps | I20: Top Set Vol | J20: Hit Top? | K20: Notes
A21: 45° Back Extension | B21: 8-12 | C21: 25 | D21: 16 | E21: 25 | F21: 18 | G21: 25 | H21: 20 | I21: =IF(AND(G21<>"",H21<>""),G21*H21,"") -> 500 | J21: =IF(H21="","",IF(H21>=VALUE(LEFT(MID(B21,FIND("-",B21)+1,2),2)),"✓","")) -> ✓
A22: DB Floor Press / Push-Up | B22: 8-12 | C22: 135 | D22: 20 | E22: 135 | F22: 17 | G22: 135 | H22: 16 | I22: =IF(AND(G22<>"",H22<>""),G22*H22,"") -> 2160 | J22: =IF(H22="","",IF(H22>=VALUE(LEFT(MID(B22,FIND("-",B22)+1,2),2)),"✓","")) -> ✓
A23: One-Arm DB Row | B23: 8-12 / side | C23: 70 | D23: 8 | E23: 70 | F23: 8 | G23: 70 | H23: 8 | I23: =IF(AND(G23<>"",H23<>""),G23*H23,"") -> 560 | J23: =IF(H23="","",IF(H23>=VALUE(LEFT(MID(B23,FIND("-",B23)+1,2),2)),"✓",""))
A24: DB Reverse Lunge | B24: 12-15 / leg | C24: 15 | D24: 15 | E24: 15 | F24: 15 | G24: 15 | H24: 15 | I24: =IF(AND(G24<>"",H24<>""),G24*H24,"") -> 225 | J24: =IF(H24="","",IF(H24>=VALUE(LEFT(MID(B24,FIND("-",B24)+1,2),2)),"✓","")) -> ✓
A25: Pull-Up / Lat Pulldown | B25: 8-12 | C25: 110 | D25: 10 | E25: 110 | F25: 9 | G25: 110 | H25: 9 | I25: =IF(AND(G25<>"",H25<>""),G25*H25,"") -> 990 | J25: =IF(H25="","",IF(H25>=VALUE(LEFT(MID(B25,FIND("-",B25)+1,2),2)),"✓",""))
A28: Blue cells = your inputs. Top Set Vol & Hit Top? auto-calculate.

Sheet Wk11
A1: Week 11 — Peak (RIR 0-1)
A3: Upper
A4: Exercise | B4: Target Reps | C4: S1 Wt | D4: S1 Reps | E4: S2 Wt | F4: S2 Reps | G4: S3 Wt | H4: S3 Reps | I4: Top Set Vol | J4: Hit Top? | K4: Notes
A5: DB Bench Press (neutral/30° incline) | B5: 8-12 | C5: 45 | D5: 12 | E5: 45 | F5: 12 | G5: 45 | H5: 8 | I5: =IF(AND(G5<>"",H5<>""),G5*H5,"") -> 360 | J5: =IF(H5="","",IF(H5>=VALUE(LEFT(MID(B5,FIND("-",B5)+1,2),2)),"✓",""))
A6: Chest-Supported DB Row | B6: 8-12 | C6: 50 | D6: 10 | E6: 50 | F6: 8 | G6: 50 | H6: 9 | I6: =IF(AND(G6<>"",H6<>""),G6*H6,"") -> 450 | J6: =IF(H6="","",IF(H6>=VALUE(LEFT(MID(B6,FIND("-",B6)+1,2),2)),"✓",""))
A7: Seated DB Shoulder Press | B7: 8-12 | C7: 30 | D7: 12 | E7: 30 | F7: 12 | G7: 30 | H7: 12 | I7: =IF(AND(G7<>"",H7<>""),G7*H7,"") -> 360 | J7: =IF(H7="","",IF(H7>=VALUE(LEFT(MID(B7,FIND("-",B7)+1,2),2)),"✓","")) -> ✓
A8: DB Lateral Raise | B8: 12-15 | C8: 15 | D8: 12 | E8: 15 | F8: 12 | G8: 15 | H8: 12 | I8: =IF(AND(G8<>"",H8<>""),G8*H8,"") -> 180 | J8: =IF(H8="","",IF(H8>=VALUE(LEFT(MID(B8,FIND("-",B8)+1,2),2)),"✓",""))
A9: DB Hammer Curl + OH Triceps Ext (SS) | B9: 12-15 | C9: 25 | D9: 15 | E9: 25 | F9: 12 | G9: 25 | H9: 15 | I9: =IF(AND(G9<>"",H9<>""),G9*H9,"") -> 375 | J9: =IF(H9="","",IF(H9>=VALUE(LEFT(MID(B9,FIND("-",B9)+1,2),2)),"✓","")) -> ✓
B10: 12-15 | C10: 45 | D10: 15 | E10: 45 | F10: 12 | G10: 45 | H10: 12 | I10: =IF(AND(G10<>"",H10<>""),G10*H10,"") -> 540 | J10: =IF(H10="","",IF(H10>=VALUE(LEFT(MID(B10,FIND("-",B10)+1,2),2)),"✓",""))
A11: Lower
A12: Exercise | B12: Target Reps | C12: S1 Wt | D12: S1 Reps | E12: S2 Wt | F12: S2 Reps | G12: S3 Wt | H12: S3 Reps | I12: Top Set Vol | J12: Hit Top? | K12: Notes
A13: Box squat | B13: 8-12 | C13: 140 | D13: 12 | E13: 140 | F13: 12 | G13: 145 | H13: 12 | I13: =IF(AND(G13<>"",H13<>""),G13*H13,"") -> 1740 | J13: =IF(H13="","",IF(H13>=VALUE(LEFT(MID(B13,FIND("-",B13)+1,2),2)),"✓","")) -> ✓
A14: Lying / Seated Leg Curl | B14: 8-12 | C14: 110 | D14: 12 | E14: 110 | F14: 9 | G14: 110 | H14: 8 | I14: =IF(AND(G14<>"",H14<>""),G14*H14,"") -> 880 | J14: =IF(H14="","",IF(H14>=VALUE(LEFT(MID(B14,FIND("-",B14)+1,2),2)),"✓",""))
A15: Smith Bulgarian Split Squat | B15: 8-12 / leg | C15: 40 | D15: 12 | E15: 40 | F15: 12 | G15: 40 | H15: 12 | I15: =IF(AND(G15<>"",H15<>""),G15*H15,"") -> 480 | J15: =IF(H15="","",IF(H15>=VALUE(LEFT(MID(B15,FIND("-",B15)+1,2),2)),"✓","")) -> ✓
A16: DB Hip Thrust | B16: 12-15 | C16: 145 | D16: 15 | E16: 145 | F16: 15 | G16: 145 | H16: 15 | I16: =IF(AND(G16<>"",H16<>""),G16*H16,"") -> 2175 | J16: =IF(H16="","",IF(H16>=VALUE(LEFT(MID(B16,FIND("-",B16)+1,2),2)),"✓","")) -> ✓
A17: Leg Extension + Standing Calf Raise (SS) | B17: 12-15 / 12-15 | C17: 120 | D17: 15 | E17: 120 | F17: 14 | G17: 120 | H17: 15 | I17: =IF(AND(G17<>"",H17<>""),G17*H17,"") -> 1800 | J17: =IF(H17="","",IF(H17>=VALUE(LEFT(MID(B17,FIND("-",B17)+1,2),2)),"✓","")) -> ✓
B18: 12-15 / 12-15 | C18: 80 | D18: 15 | E18: 80 | F18: 15 | G18: 80 | H18: 15 | I18: =IF(AND(G18<>"",H18<>""),G18*H18,"") -> 1200 | J18: =IF(H18="","",IF(H18>=VALUE(LEFT(MID(B18,FIND("-",B18)+1,2),2)),"✓","")) -> ✓
A19: Full Body
A20: Exercise | B20: Target Reps | C20: S1 Wt | D20: S1 Reps | E20: S2 Wt | F20: S2 Reps | G20: S3 Wt | H20: S3 Reps | I20: Top Set Vol | J20: Hit Top? | K20: Notes
A21: 45° Back Extension | B21: 8-12 | C21: 20 | D21: 20 | E21: 25 | F21: 18 | G21: 25 | H21: 20 | I21: =IF(AND(G21<>"",H21<>""),G21*H21,"") -> 500 | J21: =IF(H21="","",IF(H21>=VALUE(LEFT(MID(B21,FIND("-",B21)+1,2),2)),"✓","")) -> ✓
A22: DB Floor Press / Push-Up | B22: 8-12 | C22: 135 | D22: 15 | E22: 135 | F22: 15 | G22: 135 | H22: 15 | I22: =IF(AND(G22<>"",H22<>""),G22*H22,"") -> 2025 | J22: =IF(H22="","",IF(H22>=VALUE(LEFT(MID(B22,FIND("-",B22)+1,2),2)),"✓","")) -> ✓
A23: One-Arm DB Row | B23: 8-12 / side | C23: 70 | D23: 9 | E23: 70 | F23: 10 | G23: 70 | H23: 10 | I23: =IF(AND(G23<>"",H23<>""),G23*H23,"") -> 700 | J23: =IF(H23="","",IF(H23>=VALUE(LEFT(MID(B23,FIND("-",B23)+1,2),2)),"✓",""))
A24: DB Reverse Lunge | B24: 12-15 / leg | C24: 15 | D24: 15 | E24: 20 | F24: 15 | G24: 20 | H24: 15 | I24: =IF(AND(G24<>"",H24<>""),G24*H24,"") -> 300 | J24: =IF(H24="","",IF(H24>=VALUE(LEFT(MID(B24,FIND("-",B24)+1,2),2)),"✓","")) -> ✓
A25: Pull-Up / Lat Pulldown | B25: 8-12 | C25: 100 | D25: 15 | E25: 110 | F25: 9 | G25: 110 | H25: 8 | I25: =IF(AND(G25<>"",H25<>""),G25*H25,"") -> 880 | J25: =IF(H25="","",IF(H25>=VALUE(LEFT(MID(B25,FIND("-",B25)+1,2),2)),"✓",""))
A28: Blue cells = your inputs. Top Set Vol & Hit Top? auto-calculate.

Sheet Wk12
A1: Week 12 — Deload (50% wt, 2x8)
A3: Upper
A4: Exercise | B4: Target Reps | C4: S1 Wt | D4: S1 Reps | E4: S2 Wt | F4: S2 Reps | G4: S3 Wt | H4: S3 Reps | I4: Top Set Vol | J4: Hit Top? | K4: Notes
A5: DB Bench Press (neutral/30° incline) | B5: 8-12 | C5: 25 | D5: 12 | E5: 25 | F5: 12 | I5: =IF(AND(G5<>"",H5<>""),G5*H5,"") | J5: =IF(H5="","",IF(H5>=VALUE(LEFT(MID(B5,FIND("-",B5)+1,2),2)),"✓",""))
A6: Chest-Supported DB Row | B6: 8-12 | C6: 25 | D6: 12 | E6: 25 | F6: 12 | I6: =IF(AND(G6<>"",H6<>""),G6*H6,"") | J6: =IF(H6="","",IF(H6>=VALUE(LEFT(MID(B6,FIND("-",B6)+1,2),2)),"✓",""))
A7: Seated DB Shoulder Press | B7: 8-12 | C7: 15 | D7: 12 | E7: 12 | F7: 12 | I7: =IF(AND(G7<>"",H7<>""),G7*H7,"") | J7: =IF(H7="","",IF(H7>=VALUE(LEFT(MID(B7,FIND("-",B7)+1,2),2)),"✓",""))
A8: DB Lateral Raise | B8: 12-15 | C8: 10 | D8: 12 | E8: 10 | F8: 12 | I8: =IF(AND(G8<>"",H8<>""),G8*H8,"") | J8: =IF(H8="","",IF(H8>=VALUE(LEFT(MID(B8,FIND("-",B8)+1,2),2)),"✓",""))
A9: DB Hammer Curl + OH Triceps Ext (SS) | B9: 12-15 | C9: 15 | D9: 12 | E9: 15 | F9: 12 | I9: =IF(AND(G9<>"",H9<>""),G9*H9,"") | J9: =IF(H9="","",IF(H9>=VALUE(LEFT(MID(B9,FIND("-",B9)+1,2),2)),"✓",""))
C10: 25 | D10: 12 | E10: 25 | F10: 12
A11: Lower
A12: Exercise | B12: Target Reps | C12: S1 Wt | D12: S1 Reps | E12: S2 Wt | F12: S2 Reps | G12: S3 Wt | H12: S3 Reps | I12: Top Set Vol | J12: Hit Top? | K12: Notes
A13: Box squat | B13: 8-12 | C13: 75 | D13: 15 | E13: 75 | F13: 15 | I13: =IF(AND(G13<>"",H13<>""),G13*H13,"") | J13: =IF(H13="","",IF(H13>=VALUE(LEFT(MID(B13,FIND("-",B13)+1,2),2)),"✓",""))
A14: Lying / Seated Leg Curl | B14: 8-12 | C14: 60 | D14: 12 | E14: 60 | F14: 12 | I14: =IF(AND(G14<>"",H14<>""),G14*H14,"") | J14: =IF(H14="","",IF(H14>=VALUE(LEFT(MID(B14,FIND("-",B14)+1,2),2)),"✓",""))
A15: Smith Bulgarian Split Squat | B15: 8-12 / leg | C15: 20 | D15: 12 | E15: 20 | F15: 12 | I15: =IF(AND(G15<>"",H15<>""),G15*H15,"") | J15: =IF(H15="","",IF(H15>=VALUE(LEFT(MID(B15,FIND("-",B15)+1,2),2)),"✓",""))
A16: DB Hip Thrust | B16: 12-15 | C16: 75 | D16: 15 | E16: 75 | F16: 15 | I16: =IF(AND(G16<>"",H16<>""),G16*H16,"") | J16: =IF(H16="","",IF(H16>=VALUE(LEFT(MID(B16,FIND("-",B16)+1,2),2)),"✓",""))
A17: Leg Extension + Standing Calf Raise (SS) | B17: 12-15 / 12-15 | C17: 60 | D17: 15 | E17: 60 | F17: 15 | I17: =IF(AND(G17<>"",H17<>""),G17*H17,"") | J17: =IF(H17="","",IF(H17>=VALUE(LEFT(MID(B17,FIND("-",B17)+1,2),2)),"✓",""))
B18: 12-15 / 12-15 | C18: 40 | D18: 15 | E18: 40 | F18: 15 | I18: =IF(AND(G18<>"",H18<>""),G18*H18,"") | J18: =IF(H18="","",IF(H18>=VALUE(LEFT(MID(B18,FIND("-",B18)+1,2),2)),"✓",""))
A19: Full Body
A20: Exercise | B20: Target Reps | C20: S1 Wt | D20: S1 Reps | E20: S2 Wt | F20: S2 Reps | G20: S3 Wt | H20: S3 Reps | I20: Top Set Vol | J20: Hit Top? | K20: Notes
A21: 45° Back Extension | B21: 8-12 | C21: 15 | D21: 16 | E21: 15 | F21: 15 | I21: =IF(AND(G21<>"",H21<>""),G21*H21,"") | J21: =IF(H21="","",IF(H21>=VALUE(LEFT(MID(B21,FIND("-",B21)+1,2),2)),"✓",""))
A22: DB Floor Press / Push-Up | B22: 8-12 | C22: 35 | D22: 12 | E22: 35 | F22: 12 | I22: =IF(AND(G22<>"",H22<>""),G22*H22,"") | J22: =IF(H22="","",IF(H22>=VALUE(LEFT(MID(B22,FIND("-",B22)+1,2),2)),"✓",""))
A23: One-Arm DB Row | B23: 8-12 / side | C23: 40 | D23: 12 | E23: 40 | F23: 12 | I23: =IF(AND(G23<>"",H23<>""),G23*H23,"") | J23: =IF(H23="","",IF(H23>=VALUE(LEFT(MID(B23,FIND("-",B23)+1,2),2)),"✓",""))
A24: DB Reverse Lunge | B24: 12-15 / leg | C24: 10 | D24: 12 | E24: 10 | I24: =IF(AND(G24<>"",H24<>""),G24*H24,"") | J24: =IF(H24="","",IF(H24>=VALUE(LEFT(MID(B24,FIND("-",B24)+1,2),2)),"✓",""))
A25: Pull-Up / Lat Pulldown | B25: 8-12 | C25: 60 | D25: 12 | E25: 60 | I25: =IF(AND(G25<>"",H25<>""),G25*H25,"") | J25: =IF(H25="","",IF(H25>=VALUE(LEFT(MID(B25,FIND("-",B25)+1,2),2)),"✓",""))
A28: Blue cells = your inputs. Top Set Vol & Hit Top? auto-calculate.

Sheet Progress
A1: Top Set Progression — Weight × Reps (Set 3) per Week
A2: Workout | B2: Exercise | C2: Wk01 | D2: Wk02 | E2: Wk03 | F2: Wk04 | G2: Wk05 | H2: Wk06 | I2: Wk07 | J2: Wk08 | K2: Wk09 | L2: Wk10 | M2: Wk11 | N2: Wk12 | O2: Best Vol
A3: Upper | B3: DB Bench Press (neutral/30° incline) | C3: =IF('Wk01'!I4="","",'Wk01'!I4) -> Top Set Vol | D3: =IF('Wk02'!I4="","",'Wk02'!I4) -> Top Set Vol | E3: =IF('Wk03'!I4="","",'Wk03'!I4) -> Top Set Vol | F3: =IF('Wk04'!I4="","",'Wk04'!I4) -> Top Set Vol | G3: =IF('Wk05'!I4="","",'Wk05'!I4) -> Top Set Vol | H3: =IF('Wk06'!I4="","",'Wk06'!I4) -> Top Set Vol | I3: =IF('Wk07'!I4="","",'Wk07'!I4) -> Top Set Vol | J3: =IF('Wk08'!I4="","",'Wk08'!I4) -> Top Set Vol | K3: =IF('Wk09'!I4="","",'Wk09'!I4) -> Top Set Vol | L3: =IF('Wk10'!I4="","",'Wk10'!I4) -> Top Set Vol | M3: =IF('Wk11'!I4="","",'Wk11'!I4) -> Top Set Vol | N3: =IF('Wk12'!I4="","",'Wk12'!I4) -> Top Set Vol | O3: =IFERROR(MAX(C3:N3),"") -> 0
A4: Upper | B4: Chest-Supported DB Row | C4: =IF('Wk01'!I5="","",'Wk01'!I5) -> 350 | D4: =IF('Wk02'!I5="","",'Wk02'!I5) -> 320 | E4: =IF('Wk03'!I5="","",'Wk03'!I5) -> 360 | F4: =IF('Wk04'!I5="","",'Wk04'!I5) -> 360 | G4: =IF('Wk05'!I5="","",'Wk05'!I5) -> 360 | H4: =IF('Wk06'!I5="","",'Wk06'!I5) -> 360 | I4: =IF('Wk07'!I5="","",'Wk07'!I5) -> 360 | J4: =IF('Wk08'!I5="","",'Wk08'!I5) -> 405 | K4: =IF('Wk09'!I5="","",'Wk09'!I5) -> 360 | L4: =IF('Wk10'!I5="","",'Wk10'!I5) -> 360 | M4: =IF('Wk11'!I5="","",'Wk11'!I5) -> 360 | N4: =IF('Wk12'!I5="","",'Wk12'!I5) | O4: =IFERROR(MAX(C4:N4),"") -> 405
A5: Upper | B5: Seated DB Shoulder Press | C5: =IF('Wk01'!I6="","",'Wk01'!I6) -> 420 | D5: =IF('Wk02'!I6="","",'Wk02'!I6) -> 440 | E5: =IF('Wk03'!I6="","",'Wk03'!I6) -> 480 | F5: =IF('Wk04'!I6="","",'Wk04'!I6) -> 480 | G5: =IF('Wk05'!I6="","",'Wk05'!I6) -> 495 | H5: =IF('Wk06'!I6="","",'Wk06'!I6) -> 400 | I5: =IF('Wk07'!I6="","",'Wk07'!I6) -> 400 | J5: =IF('Wk08'!I6="","",'Wk08'!I6) -> 400 | K5: =IF('Wk09'!I6="","",'Wk09'!I6) -> 405 | L5: =IF('Wk10'!I6="","",'Wk10'!I6) -> 400 | M5: =IF('Wk11'!I6="","",'Wk11'!I6) -> 450 | N5: =IF('Wk12'!I6="","",'Wk12'!I6) | O5: =IFERROR(MAX(C5:N5),"") -> 495
A6: Upper | B6: DB Lateral Raise | C6: =IF('Wk01'!I7="","",'Wk01'!I7) -> 250 | D6: =IF('Wk02'!I7="","",'Wk02'!I7) -> 300 | E6: =IF('Wk03'!I7="","",'Wk03'!I7) -> 280 | F6: =IF('Wk04'!I7="","",'Wk04'!I7) -> 300 | G6: =IF('Wk05'!I7="","",'Wk05'!I7) -> 300 | H6: =IF('Wk06'!I7="","",'Wk06'!I7) -> 300 | I6: =IF('Wk07'!I7="","",'Wk07'!I7) -> 240 | J6: =IF('Wk08'!I7="","",'Wk08'!I7) -> 270 | K6: =IF('Wk09'!I7="","",'Wk09'!I7) -> 240 | L6: =IF('Wk10'!I7="","",'Wk10'!I7) -> 360 | M6: =IF('Wk11'!I7="","",'Wk11'!I7) -> 360 | N6: =IF('Wk12'!I7="","",'Wk12'!I7) | O6: =IFERROR(MAX(C6:N6),"") -> 360
A7: Upper | B7: DB Hammer Curl + OH Triceps Ext (SS) | C7: =IF('Wk01'!I8="","",'Wk01'!I8) -> 225 | D7: =IF('Wk02'!I8="","",'Wk02'!I8) -> 225 | E7: =IF('Wk03'!I8="","",'Wk03'!I8) -> 180 | F7: =IF('Wk04'!I8="","",'Wk04'!I8) -> 225 | G7: =IF('Wk05'!I8="","",'Wk05'!I8) -> 225 | H7: =IF('Wk06'!I8="","",'Wk06'!I8) -> 225 | I7: =IF('Wk07'!I8="","",'Wk07'!I8) -> 225 | J7: =IF('Wk08'!I8="","",'Wk08'!I8) -> 150 | K7: =IF('Wk09'!I8="","",'Wk09'!I8) -> 120 | L7: =IF('Wk10'!I8="","",'Wk10'!I8) -> 180 | M7: =IF('Wk11'!I8="","",'Wk11'!I8) -> 180 | N7: =IF('Wk12'!I8="","",'Wk12'!I8) | O7: =IFERROR(MAX(C7:N7),"") -> 225
A9: Lower | B9: Goblet / Front-Rack DB Squat | C9: =IF('Wk01'!I11="","",'Wk01'!I11) | D9: =IF('Wk02'!I11="","",'Wk02'!I11) | E9: =IF('Wk03'!I11="","",'Wk03'!I11) | F9: =IF('Wk04'!I11="","",'Wk04'!I11) | G9: =IF('Wk05'!I11="","",'Wk05'!I11) | H9: =IF('Wk06'!I11="","",'Wk06'!I11) | I9: =IF('Wk07'!I11="","",'Wk07'!I11) | J9: =IF('Wk08'!I11="","",'Wk08'!I11) | K9: =IF('Wk09'!I11="","",'Wk09'!I11) | L9: =IF('Wk10'!I11="","",'Wk10'!I11) | M9: =IF('Wk11'!I11="","",'Wk11'!I11) | N9: =IF('Wk12'!I11="","",'Wk12'!I11) | O9: =IFERROR(MAX(C9:N9),"") -> 0
A10: Lower | B10: Lying / Seated Leg Curl | C10: =IF('Wk01'!I12="","",'Wk01'!I12) -> Top Set Vol | D10: =IF('Wk02'!I12="","",'Wk02'!I12) -> Top Set Vol | E10: =IF('Wk03'!I12="","",'Wk03'!I12) -> Top Set Vol | F10: =IF('Wk04'!I12="","",'Wk04'!I12) -> Top Set Vol | G10: =IF('Wk05'!I12="","",'Wk05'!I12) -> Top Set Vol | H10: =IF('Wk06'!I12="","",'Wk06'!I12) -> Top Set Vol | I10: =IF('Wk07'!I12="","",'Wk07'!I12) -> Top Set Vol | J10: =IF('Wk08'!I12="","",'Wk08'!I12) -> Top Set Vol | K10: =IF('Wk09'!I12="","",'Wk09'!I12) -> Top Set Vol | L10: =IF('Wk10'!I12="","",'Wk10'!I12) -> Top Set Vol | M10: =IF('Wk11'!I12="","",'Wk11'!I12) -> Top Set Vol | N10: =IF('Wk12'!I12="","",'Wk12'!I12) -> Top Set Vol | O10: =IFERROR(MAX(C10:N10),"") -> 0
A11: Lower | B11: DB Bulgarian Split Squat | C11: =IF('Wk01'!I13="","",'Wk01'!I13) -> 1380 | D11: =IF('Wk02'!I13="","",'Wk02'!I13) -> 1380 | E11: =IF('Wk03'!I13="","",'Wk03'!I13) -> 1200 | F11: =IF('Wk04'!I13="","",'Wk04'!I13) -> 1440 | G11: =IF('Wk05'!I13="","",'Wk05'!I13) -> 1500 | H11: =IF('Wk06'!I13="","",'Wk06'!I13) | I11: =IF('Wk07'!I13="","",'Wk07'!I13) -> 1250 | J11: =IF('Wk08'!I13="","",'Wk08'!I13) -> 1350 | K11: =IF('Wk09'!I13="","",'Wk09'!I13) -> 1260 | L11: =IF('Wk10'!I13="","",'Wk10'!I13) -> 1260 | M11: =IF('Wk11'!I13="","",'Wk11'!I13) -> 1740 | N11: =IF('Wk12'!I13="","",'Wk12'!I13) | O11: =IFERROR(MAX(C11:N11),"") -> 1740
